Workbook

Sheet index
B2: Normal Time | D2: % | E2: Completed
B3: Pressure | C3: =COUNTIF('Tx Detail List'!C:C,"*CP*") | D3: =C3/C9% | E3: =(C7/C9)
B4: Flow | C4: =COUNTIF('Tx Detail List'!C:C,"*CF*") | D4: =C4/C9%
B5: Temperature | C5: =COUNTIF('Tx Detail List'!C:C,"*CT*") | D5: =C5/C9%
B6: Level | C6: =COUNTIF('Tx Detail List'!C:C,"*CL*") | D6: =C6/C9%
B7: Calibrated Total | C7: =COUNTIF('Tx Detail List'!N:N,"Calibrated") | D7: =(C7/C9)*100
B8: Waiting Total | C8: =COUNTIF('Tx Detail List'!N:N,"Waiting") | D8: =(C8/C9)*100
B9: Total Tx | C9: =C7+C8
B12: KIPP00* | C12: =COUNTIF('Tx Detail List'!B:B,B12)
B13: KIPP10* | C13: =COUNTIF('Tx Detail List'!B:B,B13)
B14: KIPP11* | C14: =COUNTIF('Tx Detail List'!B:B,B14)
B15: KIPP12* | C15: =COUNTIF('Tx Detail List'!B:B,B15)

Sheet Tx Detail List
C1: 1 | D1: 2 | E1: 3 | F1: 4 | G1: 5 | H1: 6 | I1: 7 | J1: 8 | K1: 9 | L1: 10 | M1: 11 | N1: 12 | O1: 13 | P1: 14 | Q1: 15 | R1: 16 | S1: 17 | T1: 18
A2: No | B2: Group | C2: Functional Location | D2: Description | E2: Calibration Date | F2: Sensor LRV | G2: Sensor URV | H2: Calibrated LRV | I2: Calibrated URV | J2: Unit | K2: Customer | L2: Sensor Model | M2: Tx Serial No. | N2: Tx Status | O2: SAP Ekipman Kodu | P2: Order Type | Q2: SAP Status | R2: Full Model Number | S2: Panel KKS | T2: Comments
A3: 1 | B3: KIPP00 | C3: 00GHC01CP101 | D3: DEMIN WATER PUMP-A SUCTION PRESS. | E3: 2026-04-13 | F3: -1 | G3: 20 | H3: -1 | I3: 4 | J3: Bar | K3: YOKOGAWA | L3: EJA530E | M3: 91S313262 | N3: =IF(E3="","Waiting","Calibrated") | P3: ZM06
A4: 2 | B4: KIPP00 | C4: 00GHC01CP102 | D4: DEMIN WATER PUMP-A SUCTION FILTER DP | F4: -5000 | G4: 5000 | H4: 0 | I4: 1500 | J4: mBar | K4: YOKOGAWA | L4: EJA110E | M4: 91S313090 | N4: =IF(E4="","Waiting","Calibrated") | P4: ZM06
A5: 3 | B5: KIPP00 | C5: 00GHC02CP101 | D5: DEMIN WATER PUMP-B SUCTION PRESS. | F5: -1 | G5: 20 | H5: -1 | I5: 4 | J5: Bar | K5: YOKOGAWA | L5: EJA530E | M5: 91S313263 | N5: =IF(E5="","Waiting","Calibrated") | P5: ZM06 | S5: 10LAA00GH101 | T5: Atm. Basıncı 0,935 Bar
A6: 4 | B6: KIPP00 | C6: 00GHC02CP102 | D6: DEMIN WATER PUMP-B SUCTION FILTER DP | F6: -5000 | G6: 5000 | H6: 0 | I6: 1500 | J6: mBar | K6: YOKOGAWA | L6: EJA110E | M6: 91S313091 | N6: =IF(E6="","Waiting","Calibrated") | P6: ZM06 | S6: 10LAA00GH101 | T6: Atm. Basıncı 0,935 Bar
A7: 5 | B7: KIPP00 | C7: 00GHC03CP101 | D7: DEMIN WATER PUMP-C SUCTION PRESS. | F7: -1 | G7: 20 | H7: -1 | I7: 4 | J7: Bar | K7: YOKOGAWA | L7: EJA530E | M7: 91S313264 | N7: =IF(E7="","Waiting","Calibrated") | P7: ZM06 | S7: 10LAA00GH101 | T7: Atm. Basıncı 0,935 Bar
A8: 6 | B8: KIPP00 | C8: 00GHC03CP102 | D8: DEMIN WATER PUMP-C SUCTION FILTER DP | F8: -5000 | G8: 5000 | H8: 0 | I8: 1500 | J8: mBar | K8: YOKOGAWA | L8: EJA110E | M8: 91S313092 | N8: =IF(E8="","Waiting","Calibrated") | P8: ZM06 | S8: 10LAB01GH101
A9: 7 | B9: KIPP00 | C9: 00GHC04CP101 | D9: EMERGENCY M/U PUMP-A SUCTION PT | F9: -1 | G9: 100 | H9: -1 | I9: 5 | J9: Bar | K9: YOKOGAWA | L9: EJA530E | M9: 91S313216 | N9: =IF(E9="","Waiting","Calibrated") | P9: ZM06 | S9: 10LAB02GH101
A10: 8 | B10: KIPP00 | C10: 00GHC04CP102 | D10: EMERGENCY M/U PUMP-A SUCTION STRAINER DP | F10: -5000 | G10: 5000 | H10: 0 | I10: 1500 | J10: mBar | K10: YOKOGAWA | L10: EJA110E | M10: 91S313106 | N10: =IF(E10="","Waiting","Calibrated") | P10: ZM06 | S10: 10LAB02GH101
A11: 9 | B11: KIPP00 | C11: 00GHC05CP101 | D11: EMERGENCY M/U PUMP-B SUCTION PT | F11: -1 | G11: 100 | H11: -1 | I11: 5 | J11: Bar | K11: YOKOGAWA | L11: EJA530E | M11: 91S313214 | N11: =IF(E11="","Waiting","Calibrated") | P11: ZM06 | S11: 10LAB06GH101
A12: 10 | B12: KIPP00 | C12: 00GHC05CP102 | D12: EMERGENCY M/U PUMP-B SUCTION STRAINER DP | F12: -5000 | G12: 5000 | H12: 0 | I12: 1500 | J12: mBar | K12: YOKOGAWA | L12: EJA110E | M12: 91S313105 | N12: =IF(E12="","Waiting","Calibrated") | P12: ZM06 | S12: 10LAB06GH101
A13: 11 | B13: KIPP00 | C13: 00GHC10CP101 | D13: DEMIN. WATER SUPPLY PUMP DISC. PRESS. A | E13: 46051 | F13: -1 | G13: 20 | H13: 0 | I13: 15 | J13: Bar | K13: YOKOGAWA | L13: EJA530E | M13: 91S313246 | N13: =IF(E13="","Waiting","Calibrated") | P13: ZM06 | S13: 10LAB06GH101
A14: 12 | B14: KIPP00 | C14: 00GHC10CP102 | D14: DEMIN. WATER SUPPLY PUMP DISC. PRESS. B | E14: 46051 | F14: -1 | G14: 20 | H14: 0 | I14: 15 | J14: Bar | K14: YOKOGAWA | L14: EJA530E | M14: 91S313247 | N14: =IF(E14="","Waiting","Calibrated") | P14: ZM06 | S14: 10LAB10GH101
A15: 13 | B15: KIPP00 | C15: 00GHC16CP101 | D15: EMERGENCY M/U DISCAHARGE PT - A | F15: -1 | G15: 100 | H15: 0 | I15: 15 | J15: Bar | K15: YOKOGAWA | L15: EJA530E | M15: 91S313302 | N15: =IF(E15="","Waiting","Calibrated") | P15: ZM06 | S15: 10LAB10GH101
A16: 14 | B16: KIPP00 | C16: 00GHC16CP102 | D16: EMERGENCY M/U DISCAHARGE PT - B | F16: -1 | G16: 100 | H16: 0 | I16: 15 | J16: Bar | K16: YOKOGAWA | L16: EJA530E | M16: 91S313303 | N16: =IF(E16="","Waiting","Calibrated") | P16: ZM06 | S16: 10LAB01GH101
A17: 15 | B17: KIPP00 | C17: 00GHC24CF101 | D17: CONDENSER MAKE UP WATER FIT | F17: -10197.2 | G17: 10197.2 | H17: 0 | I17: 5000 | J17: mmH2O | K17: YOKOGAWA | L17: EJA110E | M17: 91S313065 | N17: =IF(E17="","Waiting","Calibrated") | P17: ZM06 | S17: 10LAB02GH101
A18: 16 | B18: KIPP00 | C18: 00GKB21CP101 | D18: POTABLE WATER SUPPLY PUMP-A SUCTION PT | F18: -1 | G18: 20 | H18: -1 | I18: 4 | J18: Bar | K18: YOKOGAWA | L18: EJA530E | M18: 91S313267 | N18: =IF(E18="","Waiting","Calibrated") | P18: ZM06 | S18: 00GKB21GH01
A19: 17 | B19: KIPP00 | C19: 00GKB22CP101 | D19: POTABLE WATER SUPPLY PUMP-B SUCTION PT | F19: -1 | G19: 20 | H19: -1 | I19: 4 | J19: Bar | K19: YOKOGAWA | L19: EJA530E | M19: 91S313268 | N19: =IF(E19="","Waiting","Calibrated") | P19: ZM06 | S19: 00GKB21GH01
A20: 18 | B20: KIPP00 | C20: 00GKB30CP101 | D20: POTABLE WATER SUPPLY PUMP DISCHARGE PT - A | F20: -1 | G20: 20 | H20: 0 | I20: 9 | J20: Bar | K20: YOKOGAWA | L20: EJA530E | M20: 91S313244 | N20: =IF(E20="","Waiting","Calibrated") | P20: ZM06 | S20: 00GKB21GH01
A21: 19 | B21: KIPP00 | C21: 00GKB30CP102 | D21: POTABLE WATER SUPPLY PUMP DISCHARGE PT - B | F21: -1 | G21: 20 | H21: 0 | I21: 9 | J21: Bar | K21: YOKOGAWA | L21: EJA530E | M21: 91S313245 | N21: =IF(E21="","Waiting","Calibrated") | P21: ZM06 | S21: 00GKB21GH01
A22: 20 | B22: KIPP10 | C22: 10LAA00CL101 | D22: DEAERATOR & FW STORAGE TANK LEVEL A | F22: -10197.2 | G22: 10197.2 | H22: -2700 | I22: 0 | J22: mmH2O | K22: YOKOGAWA | L22: EJA110E | M22: 91S313099 | N22: =IF(E22="","Waiting","Calibrated") | P22: ZM06 | S22: 10LAB15GH101
A23: 21 | B23: KIPP10 | C23: 10LAA00CL102 | D23: DEAERATOR & FW STORAGE TANK LEVEL B | F23: -10197.2 | G23: 10197.2 | H23: -2700 | I23: 0 | J23: mmH2O | K23: YOKOGAWA | L23: EJA110E | M23: 91S313098 | N23: =IF(E23="","Waiting","Calibrated") | P23: ZM06 | S23: 10LAB15GH101
A24: 22 | B24: KIPP10 | C24: 10LAA00CL103 | D24: DEAERATOR & FW STORAGE TANK LEVEL C | F24: -10197.2 | G24: 10197.2 | H24: -2700 | I24: 0 | J24: mmH2O | K24: YOKOGAWA | L24: EJA110E | M24: 91S313095 | N24: =IF(E24="","Waiting","Calibrated") | P24: ZM06 | S24: 10LAB10GH101
A25: 23 | B25: KIPP10 | C25: 10LAA00CL104 | D25: DEAERATOR & FW STORAGE TANK LEVEL D | F25: -10197.2 | G25: 10197.2 | H25: -2700 | I25: 0 | J25: mmH2O | K25: YOKOGAWA | L25: EJA110E | M25: 91S313094 | N25: =IF(E25="","Waiting","Calibrated") | P25: ZM06 | S25: 10LAB10GH101
A26: 24 | B26: KIPP10 | C26: 10LAA00CL105 | D26: DEAERATOR & FW STORAGE TANK LEVEL E | F26: -10197.2 | G26: 10197.2 | H26: -2700 | I26: 0 | J26: mmH2O | K26: YOKOGAWA | L26: EJA110E | M26: 91S313093 | N26: =IF(E26="","Waiting","Calibrated") | P26: ZM06 | S26: 10LAB01GH101
... A29: 27 | B29: KIPP10 | C29: 10LAA00CP103 | D29: DEAERATOR & FW STORAGE TANK PRESSURE C | F29: -1 | G29: 20 | H29: 0 | I29: 7 | J29: Bar | K29: YOKOGAWA | L29: EJA530E | M29: 91S313280 | N29: =IF(E29="","Waiting","Calibrated") | P29: ZM06 | S29: 10LAB02GH101
A30: 28 | B30: KIPP10 | C30: 10LAB01CP102 | D30: STG 10 BOILER FWP C SUCTION PRESSURE | F30: -1 | G30: 20 | H30: 0 | I30: 5 | J30: Bar | K30: YOKOGAWA | L30: EJA530E | M30: 91S213232 | N30: =IF(E30="","Waiting","Calibrated") | P30: ZM06
A31: 29 | B31: KIPP10 | C31: 10LAB02CP102 | D31: BOILER FEED WATER PUMP B SUCTION PT | F31: -1 | G31: 20 | H31: 0 | I31: 5 | J31: Bar | K31: YOKOGAWA | L31: EJA530E | M31: 91S213233 | N31: =IF(E31="","Waiting","Calibrated") | P31: ZM06
A32: 30 | B32: KIPP10 | C32: 10LAB03CP102 | D32: STG 10 BOILER FWP C SUCTION PRESSURE | F32: -1 | G32: 20 | H32: 0 | I32: 5 | J32: Bar | K32: YOKOGAWA | L32: EJA530E | M32: 91S213234 | N32: =IF(E32="","Waiting","Calibrated") | P32: ZM06
A33: 31 | B33: KIPP10 | C33: 10LAB06CP102 | D33: CPH PUMP-A SUCTION PRESS. | F33: -1 | G33: 20 | H33: 0 | I33: 6 | J33: Bar | K33: YOKOGAWA | L33: EJA530E | M33: 91S313235 | N33: =IF(E33="","Waiting","Calibrated") | P33: ZM06
A34: 32 | B34: KIPP10 | C34: 10LAB07CP102 | D34: CPH PUMP-B SUCTION PRESS. | F34: -1 | G34: 20 | H34: 0 | I34: 6 | J34: Bar | K34: YOKOGAWA | L34: EJA530E | M34: 91S313236 | N34: =IF(E34="","Waiting","Calibrated") | P34: ZM06
A35: 33 | B35: KIPP10 | C35: 10LAB08CP102 | D35: CPH PUMP-C SUCTION PRESS. | F35: -1 | G35: 20 | H35: 0 | I35: 6 | J35: Bar | K35: YOKOGAWA | L35: EJA530E | M35: 91S313237 | N35: =IF(E35="","Waiting","Calibrated") | P35: ZM06
A36: 34 | B36: KIPP10 | C36: 10LAB10CP101 | D36: BOILER FEED WATER PUMP-A HP DISCHARGE PT | F36: -1 | G36: 500 | H36: 0 | I36: 218 | J36: Bar | K36: YOKOGAWA | L36: EJA530E | M36: 91S313320 | N36: =IF(E36="","Waiting","Calibrated") | P36: ZM06 | S36: 10LAB10GH101
A37: 35 | B37: KIPP10 | C37: 10LAB10CP102 | D37: BOILER FEED WATER PUMP-B HP DISCHARGE PT | F37: -1 | G37: 500 | H37: 0 | I37: 218 | J37: Bar | K37: YOKOGAWA | L37: EJA530E | M37: 91S313321 | N37: =IF(E37="","Waiting","Calibrated") | P37: ZM06 | S37: 10LAB10GH101
A38: 36 | B38: KIPP10 | C38: 10LAB11CF101 | D38: BOILER FEED WATER PUMP A HP DISCHARGE FT | F38: -50986 | G38: 50986 | H38: 0 | I38: 7500 | J38: mmH2O | K38: YOKOGAWA | L38: EJA110E | M38: 91S313539 | N38: =IF(E38="","Waiting","Calibrated") | P38: ZM06
A39: 37 | B39: KIPP10 | C39: 10LAB11CF102 | D39: BOILER FEED WATER PUMP A HP DISCHARGE FT | F39: -50986 | G39: 50986 | H39: 0 | I39: 7500 | J39: mmH2O | K39: YOKOGAWA | L39: EJA110E | M39: 91S313542 | N39: =IF(E39="","Waiting","Calibrated") | P39: ZM06
A40: 38 | B40: KIPP10 | C40: 10LAB11CP101 | D40: BOILER FEED WATER PUMP-A HP DISCHARGE PT | F40: -1 | G40: 500 | H40: 0 | I40: 218 | J40: Bar | K40: YOKOGAWA | L40: EJA530E | M40: 91S213317 | N40: =IF(E40="","Waiting","Calibrated") | P40: ZM06
A41: 39 | B41: KIPP10 | C41: 10LAB12CF101 | D41: BOILER FEED WATER PUMP B HP DISCHARGE FT | F41: -50986 | G41: 50986 | H41: 0 | I41: 7500 | J41: mmH2O | K41: YOKOGAWA | L41: EJA110E | M41: 91S313540 | N41: =IF(E41="","Waiting","Calibrated") | P41: ZM06
A42: 40 | B42: KIPP10 | C42: 10LAB12CF102 | D42: BOILER FEED WATER PUMP B HP DISCHARGE FT | F42: -50986 | G42: 50986 | H42: 0 | I42: 7500 | J42: mmH2O | K42: YOKOGAWA | L42: EJA110E | M42: 91S313543 | N42: =IF(E42="","Waiting","Calibrated") | P42: ZM06
...

Sheet Reject List
A1: No | B1: Functional Loc. | C1: Description | D1: Start Date | E1: Sensor LRV | F1: Sensor URV | G1: Calibrated LRV | H1: Calibrated URV | I1: Unit | J1: Customer | K1: Sensor Model | L1: Tx Serial No. | M1: Tx Status | N1: SAP Ekipman Kodu | O1: Order Type | P1: SAP Status | Q1: Comments
B2: KIPP10MAA10CT031A | C2: HP TURBINE EXHAUST THERMOCOUPLE | E2: - | F2: - | G2: - | H2: - | I2: ᵒC | J2: - | K2: - | L2: - | M2: Waiting | N2: 10296596 | O2: ZM06 | Q2: Dublicate
B3: KIPP10MAA10CT031B | C3: HP TURBINE EXHAUST THERMOCOUPLE | E3: - | F3: - | G3: - | H3: - | I3: ᵒC | J3: - | K3: - | L3: - | M3: Waiting | N3: 10296597 | O3: ZM06 | Q3: Dublicate
B4: KIPP10MAW10CT001 | C4: GLAND STEAM SEALING SYSTEM | E4: - | F4: - | G4: - | H4: - | I4: ᵒC | J4: - | K4: - | L4: - | M4: Waiting | N4: 10297154 | O4: ZM06 | Q4: Dublicate
B5: KIPP10MAW10CT002 | C5: GLAND STEAM SEALING SYSTEM | E5: - | F5: - | G5: - | H5: - | I5: ᵒC | J5: - | K5: - | L5: - | M5: Waiting | N5: 10297155 | O5: ZM06 | Q5: Dublicate
B6: KIPP12MBP41CP100 | C6: EV STG2 FUEL GAS PRESSURE MEASUREMENT | E6: 0 | F6: 275.79 | G6: 0 | H6: 70 | I6: Bar | J6: ROSEMOUNT | K6: 3051 PT | L6: - | M6: Waiting | N6: 10302853 | O6: ZM06 | Q6: For Commissionnig
B7: KIPP12MBP43CP100 | C7: EV STG1 FUEL GAS PRESSURE MEASUREMENT | E7: 0 | F7: 275.79 | G7: 0 | H7: 70 | I7: Bar | J7: ROSEMOUNT | K7: 3051 PT | L7: - | M7: Waiting | N7: 10302882 | O7: ZM06 | Q7: For Commissionnig
B8: KIPP11MBP41CP100 | C8: EV STG2 FUEL GAS PRESSURE MEASUREMENT | E8: 0 | F8: 275.79 | G8: 0 | H8: 70 | I8: Bar | J8: ROSEMOUNT | K8: 3051 PT | L8: 9782036 | M8: Waiting | N8: 10300348 | O8: ZM06 | Q8: For Commissionnig
B9: KIPP11MBP43CP100 | C9: EV STG1 FUEL GAS PRESSURE MEASUREMENT | E9: 0 | F9: 275.79 | G9: 0 | H9: 70 | I9: Bar | J9: ROSEMOUNT | K9: 3051 PT | L9: - | M9: Waiting | N9: 10300377 | O9: ZM06 | Q9: For Commissionnig

Sheet Kalibrasyon Ekipmanları
B2: 1 | C2: 2 | D2: 3 | E2: 4 | F2: 5 | G2: 6 | H2: 7
B3: A | C3: Fluke 754 Multifunction Process Calibrator | E3: Beamex Calibration Pressure Pump 0 - 700 Bar | F3: - | G3: Fluke 750P30 High Pressure Module 340 Bar
B4: B | C4: Fluke 754 Multifunction Process Calibrator | E4: Beamex Calibration Pressure Pump 0 - 700 Bar | F4: - | G4: Fluke 750P07 Gage Pressure Module 35 Bar
B5: C | C5: Fluke 754 Multifunction Process Calibrator | E5: Beamex Calibration Pressure Pump 0 - 20 Bar | F5: - | G5: Fluke 750P06 Gage Pressure Module 7 Bar
B6: D | C6: Fluke 754 Multifunction Process Calibrator | E6: Beamex Calibration Pressure Pump 0 - 20 Bar | F6: - | G6: Fluke 750PD5 Dual Range Pressure Module -1+2 Bar
B8: E | C8: Beamex MC6 | D8: - | E8: Beamex Calibration Pressure Pump 0 - 700 Bar | F8: - | G8: EXTERNAL PRESSURE MODULE EXT 100M | H8: -
B9: F | C9: Beamex MC6 | D9: - | E9: Beamex Calibration Pressure Pump 0 - 20 Bar | F9: - | G9: EXTERNAL PRESSURE MODULE EXT 250 | H9: -

Sheet PRINT
C1: 2 | D1: 4 | E1: 5 | F1: 6 | G1: 7 | H1: 8 | I1: 9 | J1: 10 | K1: 11 | L1: 10 | M1: 11 | Q1: 15
A2: No | B2: Functional Location | C2: Description | D2: Sensor LRV | E2: Sensor URV | F2: Calibrated LRV | G2: Calibrated URV | H2: Unit | I2: Customer | J2: Sensor Model | K2: Tx Serial No.
A3: 1 | B3: 00GHC24CF101 | C3: =VLOOKUP($B3,'Tx Detail List'!$C:$T,2,FALSE) | D3: =VLOOKUP($B3,'Tx Detail List'!$C:$T,4,FALSE) | E3: =VLOOKUP($B3,'Tx Detail List'!$C:$T,5,FALSE) | F3: =VLOOKUP($B3,'Tx Detail List'!$C:$T,6,FALSE) | G3: =VLOOKUP($B3,'Tx Detail List'!$C:$T,7,FALSE) | H3: =VLOOKUP($B3,'Tx Detail List'!$C:$T,8,FALSE) | I3: =VLOOKUP($B3,'Tx Detail List'!$C:$T,9,FALSE) | J3: =VLOOKUP($B3,'Tx Detail List'!$C:$T,10,FALSE) | K3: =VLOOKUP($B3,'Tx Detail List'!$C:$T,11,FALSE)
A4: 2 | B4: 10LAA00CP101 | C4: =VLOOKUP($B4,'Tx Detail List'!$C:$T,2,FALSE) | D4: =VLOOKUP($B4,'Tx Detail List'!$C:$T,4,FALSE) | E4: =VLOOKUP($B4,'Tx Detail List'!$C:$T,5,FALSE) | F4: =VLOOKUP($B4,'Tx Detail List'!$C:$T,6,FALSE) | G4: =VLOOKUP($B4,'Tx Detail List'!$C:$T,7,FALSE) | H4: =VLOOKUP($B4,'Tx Detail List'!$C:$T,8,FALSE) | I4: =VLOOKUP($B4,'Tx Detail List'!$C:$T,9,FALSE) | J4: =VLOOKUP($B4,'Tx Detail List'!$C:$T,10,FALSE) | K4: =VLOOKUP($B4,'Tx Detail List'!$C:$T,11,FALSE)
A5: 3 | B5: 10LAA00CP102 | C5: =VLOOKUP($B5,'Tx Detail List'!$C:$T,2,FALSE) | D5: =VLOOKUP($B5,'Tx Detail List'!$C:$T,4,FALSE) | E5: =VLOOKUP($B5,'Tx Detail List'!$C:$T,5,FALSE) | F5: =VLOOKUP($B5,'Tx Detail List'!$C:$T,6,FALSE) | G5: =VLOOKUP($B5,'Tx Detail List'!$C:$T,7,FALSE) | H5: =VLOOKUP($B5,'Tx Detail List'!$C:$T,8,FALSE) | I5: =VLOOKUP($B5,'Tx Detail List'!$C:$T,9,FALSE) | J5: =VLOOKUP($B5,'Tx Detail List'!$C:$T,10,FALSE) | K5: =VLOOKUP($B5,'Tx Detail List'!$C:$T,11,FALSE)
A6: 4 | B6: 10LAA00CP103 | C6: =VLOOKUP($B6,'Tx Detail List'!$C:$T,2,FALSE) | D6: =VLOOKUP($B6,'Tx Detail List'!$C:$T,4,FALSE) | E6: =VLOOKUP($B6,'Tx Detail List'!$C:$T,5,FALSE) | F6: =VLOOKUP($B6,'Tx Detail List'!$C:$T,6,FALSE) | G6: =VLOOKUP($B6,'Tx Detail List'!$C:$T,7,FALSE) | H6: =VLOOKUP($B6,'Tx Detail List'!$C:$T,8,FALSE) | I6: =VLOOKUP($B6,'Tx Detail List'!$C:$T,9,FALSE) | J6: =VLOOKUP($B6,'Tx Detail List'!$C:$T,10,FALSE) | K6: =VLOOKUP($B6,'Tx Detail List'!$C:$T,11,FALSE)
A7: 5 | B7: 10LAB01CP102 | C7: =VLOOKUP($B7,'Tx Detail List'!$C:$T,2,FALSE) | D7: =VLOOKUP($B7,'Tx Detail List'!$C:$T,4,FALSE) | E7: =VLOOKUP($B7,'Tx Detail List'!$C:$T,5,FALSE) | F7: =VLOOKUP($B7,'Tx Detail List'!$C:$T,6,FALSE) | G7: =VLOOKUP($B7,'Tx Detail List'!$C:$T,7,FALSE) | H7: =VLOOKUP($B7,'Tx Detail List'!$C:$T,8,FALSE) | I7: =VLOOKUP($B7,'Tx Detail List'!$C:$T,9,FALSE) | J7: =VLOOKUP($B7,'Tx Detail List'!$C:$T,10,FALSE) | K7: =VLOOKUP($B7,'Tx Detail List'!$C:$T,11,FALSE)
A8: 6 | B8: 10LAB02CP102 | C8: =VLOOKUP($B8,'Tx Detail List'!$C:$T,2,FALSE) | D8: =VLOOKUP($B8,'Tx Detail List'!$C:$T,4,FALSE) | E8: =VLOOKUP($B8,'Tx Detail List'!$C:$T,5,FALSE) | F8: =VLOOKUP($B8,'Tx Detail List'!$C:$T,6,FALSE) | G8: =VLOOKUP($B8,'Tx Detail List'!$C:$T,7,FALSE) | H8: =VLOOKUP($B8,'Tx Detail List'!$C:$T,8,FALSE) | I8: =VLOOKUP($B8,'Tx Detail List'!$C:$T,9,FALSE) | J8: =VLOOKUP($B8,'Tx Detail List'!$C:$T,10,FALSE) | K8: =VLOOKUP($B8,'Tx Detail List'!$C:$T,11,FALSE)
A9: 7 | B9: 10LAB03CP102 | C9: =VLOOKUP($B9,'Tx Detail List'!$C:$T,2,FALSE) | D9: =VLOOKUP($B9,'Tx Detail List'!$C:$T,4,FALSE) | E9: =VLOOKUP($B9,'Tx Detail List'!$C:$T,5,FALSE) | F9: =VLOOKUP($B9,'Tx Detail List'!$C:$T,6,FALSE) | G9: =VLOOKUP($B9,'Tx Detail List'!$C:$T,7,FALSE) | H9: =VLOOKUP($B9,'Tx Detail List'!$C:$T,8,FALSE) | I9: =VLOOKUP($B9,'Tx Detail List'!$C:$T,9,FALSE) | J9: =VLOOKUP($B9,'Tx Detail List'!$C:$T,10,FALSE) | K9: =VLOOKUP($B9,'Tx Detail List'!$C:$T,11,FALSE)
A10: 8 | B10: 10LAB06CP102 | C10: =VLOOKUP($B10,'Tx Detail List'!$C:$T,2,FALSE) | D10: =VLOOKUP($B10,'Tx Detail List'!$C:$T,4,FALSE) | E10: =VLOOKUP($B10,'Tx Detail List'!$C:$T,5,FALSE) | F10: =VLOOKUP($B10,'Tx Detail List'!$C:$T,6,FALSE) | G10: =VLOOKUP($B10,'Tx Detail List'!$C:$T,7,FALSE) | H10: =VLOOKUP($B10,'Tx Detail List'!$C:$T,8,FALSE) | I10: =VLOOKUP($B10,'Tx Detail List'!$C:$T,9,FALSE) | J10: =VLOOKUP($B10,'Tx Detail List'!$C:$T,10,FALSE) | K10: =VLOOKUP($B10,'Tx Detail List'!$C:$T,11,FALSE)
A11: 9 | B11: 10LAB07CP102 | C11: =VLOOKUP($B11,'Tx Detail List'!$C:$T,2,FALSE) | D11: =VLOOKUP($B11,'Tx Detail List'!$C:$T,4,FALSE) | E11: =VLOOKUP($B11,'Tx Detail List'!$C:$T,5,FALSE) | F11: =VLOOKUP($B11,'Tx Detail List'!$C:$T,6,FALSE) | G11: =VLOOKUP($B11,'Tx Detail List'!$C:$T,7,FALSE) | H11: =VLOOKUP($B11,'Tx Detail List'!$C:$T,8,FALSE) | I11: =VLOOKUP($B11,'Tx Detail List'!$C:$T,9,FALSE) | J11: =VLOOKUP($B11,'Tx Detail List'!$C:$T,10,FALSE) | K11: =VLOOKUP($B11,'Tx Detail List'!$C:$T,11,FALSE)
A12: 10 | B12: 10LAB08CP102 | C12: =VLOOKUP($B12,'Tx Detail List'!$C:$T,2,FALSE) | D12: =VLOOKUP($B12,'Tx Detail List'!$C:$T,4,FALSE) | E12: =VLOOKUP($B12,'Tx Detail List'!$C:$T,5,FALSE) | F12: =VLOOKUP($B12,'Tx Detail List'!$C:$T,6,FALSE) | G12: =VLOOKUP($B12,'Tx Detail List'!$C:$T,7,FALSE) | H12: =VLOOKUP($B12,'Tx Detail List'!$C:$T,8,FALSE) | I12: =VLOOKUP($B12,'Tx Detail List'!$C:$T,9,FALSE) | J12: =VLOOKUP($B12,'Tx Detail List'!$C:$T,10,FALSE) | K12: =VLOOKUP($B12,'Tx Detail List'!$C:$T,11,FALSE)
A13: 11 | B13: 10LAB10CP101 | C13: =VLOOKUP($B13,'Tx Detail List'!$C:$T,2,FALSE) | D13: =VLOOKUP($B13,'Tx Detail List'!$C:$T,4,FALSE) | E13: =VLOOKUP($B13,'Tx Detail List'!$C:$T,5,FALSE) | F13: =VLOOKUP($B13,'Tx Detail List'!$C:$T,6,FALSE) | G13: =VLOOKUP($B13,'Tx Detail List'!$C:$T,7,FALSE) | H13: =VLOOKUP($B13,'Tx Detail List'!$C:$T,8,FALSE) | I13: =VLOOKUP($B13,'Tx Detail List'!$C:$T,9,FALSE) | J13: =VLOOKUP($B13,'Tx Detail List'!$C:$T,10,FALSE) | K13: =VLOOKUP($B13,'Tx Detail List'!$C:$T,11,FALSE)
A14: 12 | B14: 10LAB10CP102 | C14: =VLOOKUP($B14,'Tx Detail List'!$C:$T,2,FALSE) | D14: =VLOOKUP($B14,'Tx Detail List'!$C:$T,4,FALSE) | E14: =VLOOKUP($B14,'Tx Detail List'!$C:$T,5,FALSE) | F14: =VLOOKUP($B14,'Tx Detail List'!$C:$T,6,FALSE) | G14: =VLOOKUP($B14,'Tx Detail List'!$C:$T,7,FALSE) | H14: =VLOOKUP($B14,'Tx Detail List'!$C:$T,8,FALSE) | I14: =VLOOKUP($B14,'Tx Detail List'!$C:$T,9,FALSE) | J14: =VLOOKUP($B14,'Tx Detail List'!$C:$T,10,FALSE) | K14: =VLOOKUP($B14,'Tx Detail List'!$C:$T,11,FALSE)
... A27: 25 | B27: 10LCA10CF101 | C27: =VLOOKUP($B27,'Tx Detail List'!$C:$T,2,FALSE) | D27: =VLOOKUP($B27,'Tx Detail List'!$C:$T,4,FALSE) | E27: =VLOOKUP($B27,'Tx Detail List'!$C:$T,5,FALSE) | F27: =VLOOKUP($B27,'Tx Detail List'!$C:$T,6,FALSE) | G27: =VLOOKUP($B27,'Tx Detail List'!$C:$T,7,FALSE) | H27: =VLOOKUP($B27,'Tx Detail List'!$C:$T,8,FALSE) | I27: =VLOOKUP($B27,'Tx Detail List'!$C:$T,9,FALSE) | J27: =VLOOKUP($B27,'Tx Detail List'!$C:$T,10,FALSE) | K27: =VLOOKUP($B27,'Tx Detail List'!$C:$T,11,FALSE)
A28: 26
A29: 27
A30: 28
A31: 29
A32: 30
A33: 31
A34: 32
A35: 33
A36: 34
A37: 35
A38: 36
A39: 37
... A85: 83
A86: No | B86: Functional Location | C86: Description | D86: Sensor LRV | E86: Sensor URV | F86: Calibrated LRV | G86: Calibrated URV | H86: Unit | I86: Customer | J86: Sensor Model | K86: Tx Serial No.
A87: 1
A88: 2
A89: 3
A90: 4
A91: 5
A92: 6
A93: 7
A94: 8
A95: 9
A96: 10
A97: 11
...

Sheet Tx Detail List (old)
C1: 1 | D1: 2 | E1: 3 | F1: 4 | G1: 5 | H1: 6 | I1: 7 | J1: 8 | K1: 9 | L1: 10 | M1: 11 | Q1: 15
A2: No | B2: Group | C2: Functional Location | D2: Description | E2: Calibration Date | F2: Sensor LRV | G2: Sensor URV | H2: Calibrated LRV | I2: Calibrated URV | J2: Unit | K2: Customer | L2: Sensor Model | M2: Tx Serial No. | N2: Tx Status | O2: SAP Ekipman Kodu | P2: Order Type | Q2: SAP Status | R2: Full Model Number | S2: Panel KKS | T2: Comments
A3: 1 | B3: KIPP00 | C3: 00GHC01CP101 | D3: DEMIN WATER PUMP-A SUCTION PRESS. | F3: -1 | G3: 20 | H3: -1 | I3: 4 | J3: Bar | K3: YOKOGAWA | L3: EJA530E | M3: 91S313262 | N3: =IF(E3="","Waiting","Calibrated") | O3: 10291821 | P3: ZM06
A4: 2 | B4: KIPP00 | C4: 00GHC01CP102 | D4: DEMIN WATER PUMP-A SUCTION FILTER DP | F4: -5000 | G4: 5000 | H4: 0 | I4: 1500 | J4: mBar | K4: YOKOGAWA | L4: EJA110E | M4: 91S313090 | N4: =IF(E4="","Waiting","Calibrated") | O4: 10291822 | P4: ZM06
A5: 3 | B5: KIPP00 | C5: 00GHC02CP101 | D5: DEMIN WATER PUMP-B SUCTION PRESS. | F5: -1 | G5: 20 | H5: -1 | I5: 4 | J5: Bar | K5: YOKOGAWA | L5: EJA530E | M5: 91S313263 | N5: =IF(E5="","Waiting","Calibrated") | O5: 10295565 | P5: ZM06 | S5: 10LAA00GH101 | T5: Atm. Basıncı 0,935 Bar
A6: 4 | B6: KIPP00 | C6: 00GHC02CP102 | D6: DEMIN WATER PUMP-B SUCTION FILTER DP | F6: -5000 | G6: 5000 | H6: 0 | I6: 1500 | J6: mBar | K6: YOKOGAWA | L6: EJA110E | M6: 91S313091 | N6: =IF(E6="","Waiting","Calibrated") | O6: 10295566 | P6: ZM06 | S6: 10LAA00GH101 | T6: Atm. Basıncı 0,935 Bar
A7: 5 | B7: KIPP00 | C7: 00GHC03CP101 | D7: DEMIN WATER PUMP-C SUCTION PRESS. | F7: -1 | G7: 20 | H7: -1 | I7: 4 | J7: Bar | K7: YOKOGAWA | L7: EJA530E | M7: 91S313264 | N7: =IF(E7="","Waiting","Calibrated") | O7: 10295567 | P7: ZM06 | S7: 10LAA00GH101 | T7: Atm. Basıncı 0,935 Bar
A8: 6 | B8: KIPP00 | C8: 00GHC03CP102 | D8: DEMIN WATER PUMP-C SUCTION FILTER DP | F8: -5000 | G8: 5000 | H8: 0 | I8: 1500 | J8: mBar | K8: YOKOGAWA | L8: EJA110E | M8: 91S313092 | N8: =IF(E8="","Waiting","Calibrated") | O8: 10295582 | P8: ZM06 | S8: 10LAB01GH101
A9: 7 | B9: KIPP00 | C9: 00GHC04CP101 | D9: EMERGENCY M/U PUMP-A SUCTION PT | F9: -1 | G9: 100 | H9: -1 | I9: 5 | J9: Bar | K9: YOKOGAWA | L9: EJA530E | M9: 91S313216 | N9: =IF(E9="","Waiting","Calibrated") | O9: 10295594 | P9: ZM06 | S9: 10LAB02GH101
A10: 8 | B10: KIPP00 | C10: 00GHC04CP102 | D10: EMERGENCY M/U PUMP-A SUCTION STRAINER DP | F10: -5000 | G10: 5000 | H10: 0 | I10: 1500 | J10: mBar | K10: YOKOGAWA | L10: EJA110E | M10: 91S313106 | N10: =IF(E10="","Waiting","Calibrated") | O10: 10295606 | P10: ZM06 | S10: 10LAB02GH101
A11: 9 | B11: KIPP00 | C11: 00GHC05CP101 | D11: EMERGENCY M/U PUMP-B SUCTION PT | F11: -1 | G11: 100 | H11: -1 | I11: 5 | J11: Bar | K11: YOKOGAWA | L11: EJA530E | M11: 91S313214 | N11: =IF(E11="","Waiting","Calibrated") | O11: 10295616 | P11: ZM06 | S11: 10LAB06GH101
A12: 10 | B12: KIPP00 | C12: 00GHC05CP102 | D12: EMERGENCY M/U PUMP-B SUCTION STRAINER DP | F12: -5000 | G12: 5000 | H12: 0 | I12: 1500 | J12: mBar | K12: YOKOGAWA | L12: EJA110E | M12: 91S313105 | N12: =IF(E12="","Waiting","Calibrated") | O12: 10295627 | P12: ZM06 | S12: 10LAB06GH101
A13: 11 | B13: KIPP00 | C13: 00GHC10CP101 | D13: DEMIN. WATER SUPPLY PUMP DISC. PRESS. A | F13: -1 | G13: 20 | H13: 0 | I13: 15 | J13: Bar | K13: YOKOGAWA | L13: EJA530E | M13: 91S313246 | N13: =IF(E13="","Waiting","Calibrated") | O13: 10295638 | P13: ZM06 | Q13: OK | S13: 10LAB06GH101
A14: 12 | B14: KIPP00 | C14: 00GHC10CP102 | D14: DEMIN. WATER SUPPLY PUMP DISC. PRESS. B | F14: -1 | G14: 20 | H14: 0 | I14: 15 | J14: Bar | K14: YOKOGAWA | L14: EJA530E | M14: 91S313247 | N14: =IF(E14="","Waiting","Calibrated") | O14: 10295647 | P14: ZM06 | Q14: OK | S14: 10LAB10GH101
A15: 13 | B15: KIPP00 | C15: 00GHC16CP101 | D15: EMERGENCY M/U DISCAHARGE PT - A | F15: -1 | G15: 100 | H15: 0 | I15: 15 | J15: Bar | K15: YOKOGAWA | L15: EJA530E | M15: 91S313302 | N15: =IF(E15="","Waiting","Calibrated") | O15: 10295648 | P15: ZM06 | Q15: OK | S15: 10LAB10GH101
A16: 14 | B16: KIPP00 | C16: 00GHC16CP102 | D16: EMERGENCY M/U DISCAHARGE PT - B | F16: -1 | G16: 100 | H16: 0 | I16: 15 | J16: Bar | K16: YOKOGAWA | L16: EJA530E | M16: 91S313303 | N16: =IF(E16="","Waiting","Calibrated") | O16: 10295685 | P16: ZM06 | Q16: OK | S16: 10LAB01GH101
A17: 15 | B17: KIPP00 | C17: 00GHC24CF101 | D17: CONDENSER MAKE UP WATER FIT | F17: -10197.2 | G17: 10197.2 | H17: 0 | I17: 5000 | J17: mmH2O | K17: YOKOGAWA | L17: EJA110E | M17: 91S313065 | N17: =IF(E17="","Waiting","Calibrated") | O17: 10295720 | P17: ZM06 | S17: 10LAB02GH101
A18: 16 | B18: KIPP00 | C18: 00GKB21CP101 | D18: POTABLE WATER SUPPLY PUMP-A SUCTION PT | F18: -1 | G18: 20 | H18: -1 | I18: 4 | J18: Bar | K18: YOKOGAWA | L18: EJA530E | M18: 91S313267 | N18: =IF(E18="","Waiting","Calibrated") | O18: 10295755 | P18: ZM06 | Q18: OK | S18: 10LAB02GH101
A19: 17 | B19: KIPP00 | C19: 00GKB22CP101 | D19: POTABLE WATER SUPPLY PUMP-B SUCTION PT | F19: -1 | G19: 20 | H19: -1 | I19: 4 | J19: Bar | K19: YOKOGAWA | L19: EJA530E | M19: 91S313268 | N19: =IF(E19="","Waiting","Calibrated") | O19: 10295760 | P19: ZM06 | Q19: OK | S19: 10LAB15GH101
A20: 18 | B20: KIPP00 | C20: 00GKB30CP101 | D20: POTABLE WATER SUPPLY PUMP DISCHARGE PT - A | F20: -1 | G20: 20 | H20: 0 | I20: 9 | J20: Bar | K20: YOKOGAWA | L20: EJA530E | M20: 91S313244 | N20: =IF(E20="","Waiting","Calibrated") | O20: 10295769 | P20: ZM06 | Q20: OK | S20: 10LAB15GH101
A21: 19 | B21: KIPP00 | C21: 00GKB30CP102 | D21: POTABLE WATER SUPPLY PUMP DISCHARGE PT - B | F21: -1 | G21: 20 | H21: 0 | I21: 9 | J21: Bar | K21: YOKOGAWA | L21: EJA530E | M21: 91S313245 | N21: =IF(E21="","Waiting","Calibrated") | O21: 10295777 | P21: ZM06 | Q21: OK | S21: 10LAB15GH101
A22: 20 | B22: KIPP10 | C22: 10LAA00CL101 | D22: DEAERATOR & FW STORAGE TANK LEVEL A | F22: -10197.2 | G22: 10197.2 | H22: -2700 | I22: 0 | J22: mmH2O | K22: YOKOGAWA | L22: EJA110E | M22: 91S313099 | N22: =IF(E22="","Waiting","Calibrated") | O22: 10295785 | P22: ZM06 | Q22: OK | S22: 10LAB15GH101
A23: 21 | B23: KIPP10 | C23: 10LAA00CL102 | D23: DEAERATOR & FW STORAGE TANK LEVEL B | F23: -10197.2 | G23: 10197.2 | H23: -2700 | I23: 0 | J23: mmH2O | K23: YOKOGAWA | L23: EJA110E | M23: 91S313098 | N23: =IF(E23="","Waiting","Calibrated") | O23: 10295819 | P23: ZM06 | Q23: OK | S23: 10LAB15GH101
A24: 22 | B24: KIPP10 | C24: 10LAA00CL103 | D24: DEAERATOR & FW STORAGE TANK LEVEL C | F24: -10197.2 | G24: 10197.2 | H24: -2700 | I24: 0 | J24: mmH2O | K24: YOKOGAWA | L24: EJA110E | M24: 91S313095 | N24: =IF(E24="","Waiting","Calibrated") | O24: 10295759 | P24: ZM06 | Q24: OK | S24: 10LAB10GH101
A25: 23 | B25: KIPP10 | C25: 10LAA00CL104 | D25: DEAERATOR & FW STORAGE TANK LEVEL D | F25: -10197.2 | G25: 10197.2 | H25: -2700 | I25: 0 | J25: mmH2O | K25: YOKOGAWA | L25: EJA110E | M25: 91S313094 | N25: =IF(E25="","Waiting","Calibrated") | O25: 10295820 | P25: ZM06 | Q25: OK | S25: 10LAB10GH101
A26: 24 | B26: KIPP10 | C26: 10LAA00CL105 | D26: DEAERATOR & FW STORAGE TANK LEVEL E | F26: -10197.2 | G26: 10197.2 | H26: -2700 | I26: 0 | J26: mmH2O | K26: YOKOGAWA | L26: EJA110E | M26: 91S313093 | N26: =IF(E26="","Waiting","Calibrated") | O26: 10295831 | P26: ZM06 | Q26: OK | S26: 10LAB01GH101
A27: 25 | B27: KIPP10 | C27: 10LAA00CP101 | D27: DEAERATOR & FW STORAGE TANK PRESSURE A | F27: -1 | G27: 20 | H27: 0 | I27: 7 | J27: Bar | K27: YOKOGAWA | L27: EJA530E | M27: 91S313278 | N27: =IF(E27="","Waiting","Calibrated") | O27: 10295841 | P27: ZM06 | Q27: OK | S27: 10LAB02GH101
A28: 26 | B28: KIPP10 | C28: 10LAA00CP102 | D28: DEAERATOR & FW STORAGE TANK PRESSURE B | F28: -1 | G28: 20 | H28: 0 | I28: 7 | J28: Bar | K28: YOKOGAWA | L28: EJA530E | M28: 91S313279 | N28: =IF(E28="","Waiting","Calibrated") | O28: 10295851 | P28: ZM06 | Q28: OK | S28: 10LAB02GH101
A29: 27 | B29: KIPP10 | C29: 10LAA00CP103 | D29: DEAERATOR & FW STORAGE TANK PRESSURE C | F29: -1 | G29: 20 | H29: 0 | I29: 7 | J29: Bar | K29: YOKOGAWA | L29: EJA530E | M29: 91S313280 | N29: =IF(E29="","Waiting","Calibrated") | O29: 10296179 | P29: ZM06 | Q29: OK
A30: 28 | B30: KIPP10 | C30: 10LAB01CP102 | D30: STG 10 BOILER FWP C SUCTION PRESSURE | F30: -1 | G30: 20 | H30: 0 | I30: 5 | J30: Bar | K30: YOKOGAWA | L30: EJA530E | M30: 91S213232 | N30: =IF(E30="","Waiting","Calibrated") | O30: 10296180 | P30: ZM06 | Q30: OK
A31: 29 | B31: KIPP10 | C31: 10LAB02CP102 | D31: BOILER FEED WATER PUMP B SUCTION PT | F31: -1 | G31: 20 | H31: 0 | I31: 5 | J31: Bar | K31: YOKOGAWA | L31: EJA530E | M31: 91S213233 | N31: =IF(E31="","Waiting","Calibrated") | O31: 10296213 | P31: ZM06 | Q31: OK
A32: 30 | B32: KIPP10 | C32: 10LAB03CP102 | D32: STG 10 BOILER FWP C SUCTION PRESSURE | F32: -1 | G32: 20 | H32: 0 | I32: 5 | J32: Bar | K32: YOKOGAWA | L32: EJA530E | M32: 91S213234 | N32: =IF(E32="","Waiting","Calibrated") | O32: 10296214 | P32: ZM06 | Q32: OK
A33: 31 | B33: KIPP10 | C33: 10LAB06CP102 | D33: CPH PUMP-A SUCTION PRESS. | F33: -1 | G33: 20 | H33: 0 | I33: 6 | J33: Bar | K33: YOKOGAWA | L33: EJA530E | M33: 91S313235 | N33: =IF(E33="","Waiting","Calibrated") | O33: 10296232 | P33: ZM06 | Q33: OK
A34: 32 | B34: KIPP10 | C34: 10LAB07CP102 | D34: CPH PUMP-B SUCTION PRESS. | F34: -1 | G34: 20 | H34: 0 | I34: 6 | J34: Bar | K34: YOKOGAWA | L34: EJA530E | M34: 91S313236 | N34: =IF(E34="","Waiting","Calibrated") | O34: 10296242 | P34: ZM06 | Q34: OK
A35: 33 | B35: KIPP10 | C35: 10LAB08CP102 | D35: CPH PUMP-C SUCTION PRESS. | F35: -1 | G35: 20 | H35: 0 | I35: 6 | J35: Bar | K35: YOKOGAWA | L35: EJA530E | M35: 91S313237 | N35: =IF(E35="","Waiting","Calibrated") | O35: 10296283 | P35: ZM06 | Q35: OK
A36: 34 | B36: KIPP10 | C36: 10LAB10CP101 | D36: BOILER FEED WATER PUMP-A HP DISCHARGE PT | F36: -1 | G36: 500 | H36: 0 | I36: 218 | J36: Bar | K36: YOKOGAWA | L36: EJA530E | M36: 91S313320 | N36: =IF(E36="","Waiting","Calibrated") | O36: 10296284 | P36: ZM06 | Q36: OK
A37: 35 | B37: KIPP10 | C37: 10LAB10CP102 | D37: BOILER FEED WATER PUMP-B HP DISCHARGE PT | F37: -1 | G37: 500 | H37: 0 | I37: 218 | J37: Bar | K37: YOKOGAWA | L37: EJA530E | M37: 91S313321 | N37: =IF(E37="","Waiting","Calibrated") | O37: 10296285 | P37: ZM06 | Q37: OK
A38: 36 | B38: KIPP10 | C38: 10LAB11CF101 | D38: BOILER FEED WATER PUMP A HP DISCHARGE FT | F38: -50986 | G38: 50986 | H38: 0 | I38: 7500 | J38: mmH2O | K38: YOKOGAWA | L38: EJA110E | M38: 91S313539 | N38: =IF(E38="","Waiting","Calibrated") | O38: 10296286 | P38: ZM06 | Q38: OK
A39: 37 | B39: KIPP10 | C39: 10LAB11CF102 | D39: BOILER FEED WATER PUMP A HP DISCHARGE FT | F39: -50986 | G39: 50986 | H39: 0 | I39: 7500 | J39: mmH2O | K39: YOKOGAWA | L39: EJA110E | M39: 91S313542 | N39: =IF(E39="","Waiting","Calibrated") | O39: 10296356 | P39: ZM06 | Q39: OK
A40: 38 | B40: KIPP10 | C40: 10LAB11CP101 | D40: BOILER FEED WATER PUMP-A HP DISCHARGE PT | F40: -1 | G40: 500 | H40: 0 | I40: 218 | J40: Bar | K40: YOKOGAWA | L40: EJA530E | M40: 91S213317 | N40: =IF(E40="","Waiting","Calibrated") | O40: 10296357 | P40: ZM06 | Q40: OK
...

Sheet Backup202604_06
C1: 1 | D1: 2 | E1: 3 | F1: 4 | G1: 5 | H1: 6 | I1: 7 | J1: 8 | K1: 9 | L1: 10 | M1: 11 | N1: 12 | O1: 13 | P1: 14 | Q1: 15 | R1: 16 | S1: 17 | T1: 18
A2: No | B2: Group | C2: Functional Location | D2: Description | E2: Calibration Date | F2: Sensor LRV | G2: Sensor URV | H2: Calibrated LRV | I2: Calibrated URV | J2: Unit | K2: Customer | L2: Sensor Model | M2: Tx Serial No. | N2: Tx Status | O2: SAP Ekipman Kodu | P2: Order Type | Q2: SAP Status | R2: Full Model Number | S2: Panel KKS | T2: Comments
A3: 1 | B3: KIPP00 | C3: 00GHC01CP101 | D3: DEMIN WATER PUMP-A SUCTION PRESS. | F3: -1 | G3: 20 | H3: -1 | I3: 4 | J3: Bar | K3: YOKOGAWA | L3: EJA530E | M3: 91S313262 | N3: =IF(E3="","Waiting","Calibrated") | P3: ZM06
A4: 2 | B4: KIPP00 | C4: 00GHC01CP102 | D4: DEMIN WATER PUMP-A SUCTION FILTER DP | F4: -5000 | G4: 5000 | H4: 0 | I4: 1500 | J4: mBar | K4: YOKOGAWA | L4: EJA110E | M4: 91S313090 | N4: =IF(E4="","Waiting","Calibrated") | P4: ZM06
A5: 3 | B5: KIPP00 | C5: 00GHC02CP101 | D5: DEMIN WATER PUMP-B SUCTION PRESS. | F5: -1 | G5: 20 | H5: -1 | I5: 4 | J5: Bar | K5: YOKOGAWA | L5: EJA530E | M5: 91S313263 | N5: =IF(E5="","Waiting","Calibrated") | P5: ZM06 | S5: 10LAA00GH101 | T5: Atm. Basıncı 0,935 Bar
A6: 4 | B6: KIPP00 | C6: 00GHC02CP102 | D6: DEMIN WATER PUMP-B SUCTION FILTER DP | F6: -5000 | G6: 5000 | H6: 0 | I6: 1500 | J6: mBar | K6: YOKOGAWA | L6: EJA110E | M6: 91S313091 | N6: =IF(E6="","Waiting","Calibrated") | P6: ZM06 | S6: 10LAA00GH101 | T6: Atm. Basıncı 0,935 Bar
A7: 5 | B7: KIPP00 | C7: 00GHC03CP101 | D7: DEMIN WATER PUMP-C SUCTION PRESS. | F7: -1 | G7: 20 | H7: -1 | I7: 4 | J7: Bar | K7: YOKOGAWA | L7: EJA530E | M7: 91S313264 | N7: =IF(E7="","Waiting","Calibrated") | P7: ZM06 | S7: 10LAA00GH101 | T7: Atm. Basıncı 0,935 Bar
A8: 6 | B8: KIPP00 | C8: 00GHC03CP102 | D8: DEMIN WATER PUMP-C SUCTION FILTER DP | F8: -5000 | G8: 5000 | H8: 0 | I8: 1500 | J8: mBar | K8: YOKOGAWA | L8: EJA110E | M8: 91S313092 | N8: =IF(E8="","Waiting","Calibrated") | P8: ZM06 | S8: 10LAB01GH101
A9: 7 | B9: KIPP00 | C9: 00GHC04CP101 | D9: EMERGENCY M/U PUMP-A SUCTION PT | F9: -1 | G9: 100 | H9: -1 | I9: 5 | J9: Bar | K9: YOKOGAWA | L9: EJA530E | M9: 91S313216 | N9: =IF(E9="","Waiting","Calibrated") | P9: ZM06 | S9: 10LAB02GH101
A10: 8 | B10: KIPP00 | C10: 00GHC04CP102 | D10: EMERGENCY M/U PUMP-A SUCTION STRAINER DP | F10: -5000 | G10: 5000 | H10: 0 | I10: 1500 | J10: mBar | K10: YOKOGAWA | L10: EJA110E | M10: 91S313106 | N10: =IF(E10="","Waiting","Calibrated") | P10: ZM06 | S10: 10LAB02GH101
A11: 9 | B11: KIPP00 | C11: 00GHC05CP101 | D11: EMERGENCY M/U PUMP-B SUCTION PT | F11: -1 | G11: 100 | H11: -1 | I11: 5 | J11: Bar | K11: YOKOGAWA | L11: EJA530E | M11: 91S313214 | N11: =IF(E11="","Waiting","Calibrated") | P11: ZM06 | S11: 10LAB06GH101
A12: 10 | B12: KIPP00 | C12: 00GHC05CP102 | D12: EMERGENCY M/U PUMP-B SUCTION STRAINER DP | F12: -5000 | G12: 5000 | H12: 0 | I12: 1500 | J12: mBar | K12: YOKOGAWA | L12: EJA110E | M12: 91S313105 | N12: =IF(E12="","Waiting","Calibrated") | P12: ZM06 | S12: 10LAB06GH101
A13: 11 | B13: KIPP00 | C13: 00GHC10CP101 | D13: DEMIN. WATER SUPPLY PUMP DISC. PRESS. A | E13: 46051 | F13: -1 | G13: 20 | H13: 0 | I13: 15 | J13: Bar | K13: YOKOGAWA | L13: EJA530E | M13: 91S313246 | N13: =IF(E13="","Waiting","Calibrated") | P13: ZM06 | S13: 10LAB06GH101
A14: 12 | B14: KIPP00 | C14: 00GHC10CP102 | D14: DEMIN. WATER SUPPLY PUMP DISC. PRESS. B | E14: 46051 | F14: -1 | G14: 20 | H14: 0 | I14: 15 | J14: Bar | K14: YOKOGAWA | L14: EJA530E | M14: 91S313247 | N14: =IF(E14="","Waiting","Calibrated") | P14: ZM06 | S14: 10LAB10GH101
A15: 13 | B15: KIPP00 | C15: 00GHC16CP101 | D15: EMERGENCY M/U DISCAHARGE PT - A | F15: -1 | G15: 100 | H15: 0 | I15: 15 | J15: Bar | K15: YOKOGAWA | L15: EJA530E | M15: 91S313302 | N15: =IF(E15="","Waiting","Calibrated") | P15: ZM06 | S15: 10LAB10GH101
A16: 14 | B16: KIPP00 | C16: 00GHC16CP102 | D16: EMERGENCY M/U DISCAHARGE PT - B | F16: -1 | G16: 100 | H16: 0 | I16: 15 | J16: Bar | K16: YOKOGAWA | L16: EJA530E | M16: 91S313303 | N16: =IF(E16="","Waiting","Calibrated") | P16: ZM06 | S16: 10LAB01GH101
A17: 15 | B17: KIPP00 | C17: 00GHC24CF101 | D17: CONDENSER MAKE UP WATER FIT | F17: -10197.2 | G17: 10197.2 | H17: 0 | I17: 5000 | J17: mmH2O | K17: YOKOGAWA | L17: EJA110E | M17: 91S313065 | N17: =IF(E17="","Waiting","Calibrated") | P17: ZM06 | S17: 10LAB02GH101
A18: 16 | B18: KIPP00 | C18: 00GKB21CP101 | D18: POTABLE WATER SUPPLY PUMP-A SUCTION PT | F18: -1 | G18: 20 | H18: -1 | I18: 4 | J18: Bar | K18: YOKOGAWA | L18: EJA530E | M18: 91S313267 | N18: =IF(E18="","Waiting","Calibrated") | P18: ZM06 | S18: 00GKB21GH01
A19: 17 | B19: KIPP00 | C19: 00GKB22CP101 | D19: POTABLE WATER SUPPLY PUMP-B SUCTION PT | F19: -1 | G19: 20 | H19: -1 | I19: 4 | J19: Bar | K19: YOKOGAWA | L19: EJA530E | M19: 91S313268 | N19: =IF(E19="","Waiting","Calibrated") | P19: ZM06 | S19: 00GKB21GH01
A20: 18 | B20: KIPP00 | C20: 00GKB30CP101 | D20: POTABLE WATER SUPPLY PUMP DISCHARGE PT - A | F20: -1 | G20: 20 | H20: 0 | I20: 9 | J20: Bar | K20: YOKOGAWA | L20: EJA530E | M20: 91S313244 | N20: =IF(E20="","Waiting","Calibrated") | P20: ZM06 | S20: 00GKB21GH01
A21: 19 | B21: KIPP00 | C21: 00GKB30CP102 | D21: POTABLE WATER SUPPLY PUMP DISCHARGE PT - B | F21: -1 | G21: 20 | H21: 0 | I21: 9 | J21: Bar | K21: YOKOGAWA | L21: EJA530E | M21: 91S313245 | N21: =IF(E21="","Waiting","Calibrated") | P21: ZM06 | S21: 00GKB21GH01
A22: 20 | B22: KIPP10 | C22: 10LAA00CL101 | D22: DEAERATOR & FW STORAGE TANK LEVEL A | F22: -10197.2 | G22: 10197.2 | H22: -2700 | I22: 0 | J22: mmH2O | K22: YOKOGAWA | L22: EJA110E | M22: 91S313099 | N22: =IF(E22="","Waiting","Calibrated") | P22: ZM06 | S22: 10LAB15GH101
A23: 21 | B23: KIPP10 | C23: 10LAA00CL102 | D23: DEAERATOR & FW STORAGE TANK LEVEL B | F23: -10197.2 | G23: 10197.2 | H23: -2700 | I23: 0 | J23: mmH2O | K23: YOKOGAWA | L23: EJA110E | M23: 91S313098 | N23: =IF(E23="","Waiting","Calibrated") | P23: ZM06 | S23: 10LAB15GH101
A24: 22 | B24: KIPP10 | C24: 10LAA00CL103 | D24: DEAERATOR & FW STORAGE TANK LEVEL C | F24: -10197.2 | G24: 10197.2 | H24: -2700 | I24: 0 | J24: mmH2O | K24: YOKOGAWA | L24: EJA110E | M24: 91S313095 | N24: =IF(E24="","Waiting","Calibrated") | P24: ZM06 | S24: 10LAB10GH101
A25: 23 | B25: KIPP10 | C25: 10LAA00CL104 | D25: DEAERATOR & FW STORAGE TANK LEVEL D | F25: -10197.2 | G25: 10197.2 | H25: -2700 | I25: 0 | J25: mmH2O | K25: YOKOGAWA | L25: EJA110E | M25: 91S313094 | N25: =IF(E25="","Waiting","Calibrated") | P25: ZM06 | S25: 10LAB10GH101
A26: 24 | B26: KIPP10 | C26: 10LAA00CL105 | D26: DEAERATOR & FW STORAGE TANK LEVEL E | F26: -10197.2 | G26: 10197.2 | H26: -2700 | I26: 0 | J26: mmH2O | K26: YOKOGAWA | L26: EJA110E | M26: 91S313093 | N26: =IF(E26="","Waiting","Calibrated") | P26: ZM06 | S26: 10LAB01GH101
... A29: 27 | B29: KIPP10 | C29: 10LAA00CP103 | D29: DEAERATOR & FW STORAGE TANK PRESSURE C | F29: -1 | G29: 20 | H29: 0 | I29: 7 | J29: Bar | K29: YOKOGAWA | L29: EJA530E | M29: 91S313280 | N29: =IF(E29="","Waiting","Calibrated") | P29: ZM06 | S29: 10LAB02GH101
A30: 28 | B30: KIPP10 | C30: 10LAB01CP102 | D30: STG 10 BOILER FWP C SUCTION PRESSURE | F30: -1 | G30: 20 | H30: 0 | I30: 5 | J30: Bar | K30: YOKOGAWA | L30: EJA530E | M30: 91S213232 | N30: =IF(E30="","Waiting","Calibrated") | P30: ZM06
A31: 29 | B31: KIPP10 | C31: 10LAB02CP102 | D31: BOILER FEED WATER PUMP B SUCTION PT | F31: -1 | G31: 20 | H31: 0 | I31: 5 | J31: Bar | K31: YOKOGAWA | L31: EJA530E | M31: 91S213233 | N31: =IF(E31="","Waiting","Calibrated") | P31: ZM06
A32: 30 | B32: KIPP10 | C32: 10LAB03CP102 | D32: STG 10 BOILER FWP C SUCTION PRESSURE | F32: -1 | G32: 20 | H32: 0 | I32: 5 | J32: Bar | K32: YOKOGAWA | L32: EJA530E | M32: 91S213234 | N32: =IF(E32="","Waiting","Calibrated") | P32: ZM06
A33: 31 | B33: KIPP10 | C33: 10LAB06CP102 | D33: CPH PUMP-A SUCTION PRESS. | F33: -1 | G33: 20 | H33: 0 | I33: 6 | J33: Bar | K33: YOKOGAWA | L33: EJA530E | M33: 91S313235 | N33: =IF(E33="","Waiting","Calibrated") | P33: ZM06
A34: 32 | B34: KIPP10 | C34: 10LAB07CP102 | D34: CPH PUMP-B SUCTION PRESS. | F34: -1 | G34: 20 | H34: 0 | I34: 6 | J34: Bar | K34: YOKOGAWA | L34: EJA530E | M34: 91S313236 | N34: =IF(E34="","Waiting","Calibrated") | P34: ZM06
A35: 33 | B35: KIPP10 | C35: 10LAB08CP102 | D35: CPH PUMP-C SUCTION PRESS. | F35: -1 | G35: 20 | H35: 0 | I35: 6 | J35: Bar | K35: YOKOGAWA | L35: EJA530E | M35: 91S313237 | N35: =IF(E35="","Waiting","Calibrated") | P35: ZM06
A36: 34 | B36: KIPP10 | C36: 10LAB10CP101 | D36: BOILER FEED WATER PUMP-A HP DISCHARGE PT | F36: -1 | G36: 500 | H36: 0 | I36: 218 | J36: Bar | K36: YOKOGAWA | L36: EJA530E | M36: 91S313320 | N36: =IF(E36="","Waiting","Calibrated") | P36: ZM06 | S36: 10LAB10GH101
A37: 35 | B37: KIPP10 | C37: 10LAB10CP102 | D37: BOILER FEED WATER PUMP-B HP DISCHARGE PT | F37: -1 | G37: 500 | H37: 0 | I37: 218 | J37: Bar | K37: YOKOGAWA | L37: EJA530E | M37: 91S313321 | N37: =IF(E37="","Waiting","Calibrated") | P37: ZM06 | S37: 10LAB10GH101
A38: 36 | B38: KIPP10 | C38: 10LAB11CF101 | D38: BOILER FEED WATER PUMP A HP DISCHARGE FT | F38: -50986 | G38: 50986 | H38: 0 | I38: 7500 | J38: mmH2O | K38: YOKOGAWA | L38: EJA110E | M38: 91S313539 | N38: =IF(E38="","Waiting","Calibrated") | P38: ZM06
A39: 37 | B39: KIPP10 | C39: 10LAB11CF102 | D39: BOILER FEED WATER PUMP A HP DISCHARGE FT | F39: -50986 | G39: 50986 | H39: 0 | I39: 7500 | J39: mmH2O | K39: YOKOGAWA | L39: EJA110E | M39: 91S313542 | N39: =IF(E39="","Waiting","Calibrated") | P39: ZM06
A40: 38 | B40: KIPP10 | C40: 10LAB11CP101 | D40: BOILER FEED WATER PUMP-A HP DISCHARGE PT | F40: -1 | G40: 500 | H40: 0 | I40: 218 | J40: Bar | K40: YOKOGAWA | L40: EJA530E | M40: 91S213317 | N40: =IF(E40="","Waiting","Calibrated") | P40: ZM06
A41: 39 | B41: KIPP10 | C41: 10LAB12CF101 | D41: BOILER FEED WATER PUMP B HP DISCHARGE FT | F41: -50986 | G41: 50986 | H41: 0 | I41: 7500 | J41: mmH2O | K41: YOKOGAWA | L41: EJA110E | M41: 91S313540 | N41: =IF(E41="","Waiting","Calibrated") | P41: ZM06
A42: 40 | B42: KIPP10 | C42: 10LAB12CF102 | D42: BOILER FEED WATER PUMP B HP DISCHARGE FT | F42: -50986 | G42: 50986 | H42: 0 | I42: 7500 | J42: mmH2O | K42: YOKOGAWA | L42: EJA110E | M42: 91S313543 | N42: =IF(E42="","Waiting","Calibrated") | P42: ZM06
...

Sheet Tx  List (2)
A1: No | B1: Functional Location | C1: Description | D1: Calibration Date | E1: Sensor LRV | F1: Sensor URV | G1: Calibrated LRV | H1: Calibrated URV | I1: Unit | J1: Customer | K1: Sensor Model | L1: Tx Serial No. | M1: Tx Status | N1: SAP Ekipman Kodu | O1: Order Type | P1: SAP Status | Q1: Panel KKS | R1: Comments
A2: 1 | B2: KIPP12MBV21CP001 | E2: -1.013 | F2: 10.342 | G2: 0 | H2: 10 | I2: Bar | J2: ROSEMOUNT | K2: 2088 PT | L2: 9791825 | M2: Waiting | R2: Out of SAP list | S2: KIPP00GHC10CP101 | T2: =LEFT(B2,7)
A3: 2 | B3: KIPP12MBV21CP002 | E3: -1.013 | F3: 10.342 | G3: 0 | H3: 10 | I3: Bar | J3: ROSEMOUNT | K3: 2088 PT | L3: 9791826 | M3: Waiting | R3: Out of SAP list | S3: KIPP00GHC10CP102 | T3: =LEFT(B3,7)
A4: 3 | B4: KIPP12MBL61CP010 | E4: -6216 | F4: 6216 | G4: 0 | H4: 1000 | I4: Pa | J4: ROSEMOUNT | K4: 3051 PT | L4: 9852955 | M4: Waiting | R4: Out of SAP list | S4: KIPP10LAA00CP101 | T4: =LEFT(B4,7)
A5: 4 | B5: KIPP10LCA10CF102 | C5: CONDENSATE EXTRACTION PUMP DISCHARGE FT | E5: -10197.2 | F5: 10197.2 | G5: 0 | H5: 10000 | I5: mmH2O | J5: YOKOGAWA | K5: EJA110E | L5: 91S313101 | M5: Waiting | R5: Out of SAP list | S5: KIPP10LAA00CP102 | T5: =LEFT(B5,7)
A6: 5 | B6: KIPP10LCA01CP101 | C6: CEP-A SUC. Filter PRESS. | D6: 43877 | E6: -5000 | F6: 5000 | G6: 0 | H6: 500 | I6: mBar | J6: YOKOGAWA | K6: EJA110E | L6: 91S313075 | M6: Waiting | R6: Out of SAP list | S6: KIPP10LAA00CP103 | T6: =LEFT(B6,7)
A7: 6 | B7: KIPP10LCA02CP101 | C7: CEP-B SUC. Filter PRESS. | D7: 43877 | E7: -5000 | F7: 5000 | G7: 0 | H7: 500 | I7: mBar | J7: YOKOGAWA | K7: EJA110E | L7: 91S313076 | M7: Waiting | R7: Out of SAP list | S7: KIPP10LAB01CP102 | T7: =LEFT(B7,7)
A8: 7 | B8: KIPP10LCA03CP101 | C8: CEP-C SUC. Filter PRESS. | D8: 43877 | E8: -5000 | F8: 5000 | G8: 0 | H8: 500 | I8: mBar | J8: YOKOGAWA | K8: EJA110E | L8: 91S313077 | M8: Waiting | R8: Out of SAP list | S8: KIPP10LAB02CP102 | T8: =LEFT(B8,7)
A9: 8 | B9: 11HAC58CP001 | C9: HP DRUM FW PT | E9: 0 | F9: 689.5 | G9: 0 | H9: 300 | I9: Bar | J9: ROSEMOUNT | K9: 2051 PT | L9: 210420 | M9: Waiting | R9: Out of SAP list | S9: KIPP10LAB03CP102 | T9: =LEFT(B9,7)
A10: 9 | B10: 11HAC58CF002 | C10: HP DRUM FW FLOW A | E10: -621.6 | F10: 621.6 | G10: 0 | H10: 302 | I10: mBar | J10: ROSEMOUNT | K10: 2051 PT | L10: 214452 | M10: Waiting | R10: Out of SAP list | S10: KIPP10LAB06CP102 | T10: =LEFT(B10,7)
A11: 10 | B11: 11HAC58CF003 | C11: HP DRUM FW FLOW B | E11: -621.6 | F11: 621.6 | G11: 0 | H11: 302 | I11: mBar | J11: ROSEMOUNT | K11: 2051 PT | L11: 214453 | M11: Waiting | R11: Out of SAP list | S11: KIPP10LAB07CP102 | T11: =LEFT(B11,7)
A12: 11 | M12: Waiting | S12: KIPP10LAB08CP102 | T12: =LEFT(B12,7)
A13: 12 | M13: Waiting | S13: KIPP10LAB10CP101 | T13: =LEFT(B13,7)
A14: 13 | M14: Waiting | S14: KIPP10LAB10CP102 | T14: =LEFT(B14,7)
A15: 14 | M15: Waiting | S15: KIPP10LAB11CP101 | T15: =LEFT(B15,7)
A16: 15 | M16: Waiting | S16: KIPP10LAB12CP101 | T16: =LEFT(B16,7)
A17: 16 | M17: Waiting | S17: KIPP10LAB13CP101 | T17: =LEFT(B17,7)
A18: 17 | M18: Waiting | S18: KIPP10LAB15CP101 | T18: =LEFT(B18,7)
A19: 18 | M19: Waiting | S19: KIPP10LAB15CP102 | T19: =LEFT(B19,7)
A20: 19 | M20: Waiting | S20: KIPP10LAB16CP101 | T20: =LEFT(B20,7)
A21: 20 | M21: Waiting | S21: KIPP10LAB17CP101 | T21: =LEFT(B21,7)
A22: 21 | M22: Waiting | S22: KIPP10LAB18CP101 | T22: =LEFT(B22,7)
A23: 22 | M23: Waiting | S23: KIPP10LAB30CP101 | T23: =LEFT(B23,7)
... A302: 301 | M302: Waiting | S302: KIPP10LCA03CP102 | T302: =LEFT(B302,7)
A303: 302 | M303: Waiting | T303: =LEFT(B303,7)
A304: 303 | M304: Waiting | T304: =LEFT(B304,7)
A305: 304 | M305: Waiting | T305: =LEFT(B305,7)
A306: 305 | M306: Waiting | T306: =LEFT(B306,7)
A307: 306 | M307: Waiting | T307: =LEFT(B307,7)
A308: 307 | M308: Waiting | T308: =LEFT(B308,7)
A309: 308 | M309: Waiting | T309: =LEFT(B309,7)
A310: 309 | M310: Waiting | T310: =LEFT(B310,7)
A311: 310 | M311: Waiting | T311: =LEFT(B311,7)
A312: 311 | M312: Waiting | T312: =LEFT(B312,7)
A313: 312 | M313: Waiting | T313: =LEFT(B313,7)
A314: 313 | M314: Waiting | T314: =LEFT(B314,7)
A315: 314 | M315: Waiting | T315: =LEFT(B315,7)
A316: 315 | M316: Waiting
A317: 316 | M317: Waiting
A318: 317 | M318: Waiting
...
